<mujoco model="inverted_pendulum">
    <compiler inertiafromgeom="true"/>

    <asset>
        <texture type="skybox" builtin="gradient" rgb1="0.6 0.6 0.6" rgb2="0 0 0" width="512" height="512"/>
        <texture name="texplane" type="2d" builtin="checker" rgb1=".25 .25 .25" rgb2=".3 .3 .3" width="512" height="512" mark="cross" markrgb=".8 .8 .8"/>
        <material name="matplane" reflectance="0.3" texture="texplane" texrepeat="1 1" texuniform="true"/>
    </asset>

    <default>
        <joint armature="0" damping="1" limited="true"/>
        <geom contype="0" friction="1 0.1 0.1" rgba="0.7 0.7 0 1"/>
        <tendon/>
        <motor ctrlrange="-3 3"/>
    </default>

    <option gravity="0 0 -9.81" integrator="RK4" timestep="0.02"/>
    <size nstack="3000"/>

    <worldbody>
        <geom name="floor" pos="0 0 -0.5" size="0 0 1" type="plane" material="matplane"/>
        <light directional="true" diffuse=".8 .8 .8" specular=".2 .2 .2" pos="0 0 5" dir="0 0 -1"/>
        <geom name="rail" pos="0 0 0" quat="0.707 0 0.707 0" rgba="0.3 0.3 0.7 1" size="0.01 1" type="capsule"/>
        
        <body name="cart" pos="0 0 0">
            <inertial mass="0.48" pos="0 0 0"/>
            <joint axis="1 0 0" limited="true" name="slider" pos="0 0 0" range="-1 1" type="slide"/>
            <geom name="cart" pos="0 0 0" quat="0.707 0 0.707 0" size="0.1 0.1" type="capsule" rgba="0 0.7 0.7 1"/>
            
            <body name="pole" pos="0 0 0">
                <inertial mass="0.7332" pos="0 0 0.3"/>
                <joint axis="0 1 0" name="hinge" pos="0 0 0" range="-90 90" type="hinge"/>
                <geom fromto="0 0 0 0 0 0.6" name="cpole" rgba="0 0.7 0.7 1" size="0.049 0.3" type="capsule"/>
            </body>
        </body>
    </worldbody>

    <actuator>
        <motor ctrllimited="true" ctrlrange="-3 3" gear="100" joint="slider" name="slide"/>
    </actuator>
</mujoco>
