<mujoco model="inverted pendulum">
	<compiler inertiafromgeom="true"/>
	<default>
		<joint armature="0" damping="1" limited="true"/>
		<geom contype="0" friction="1 0.1 0.1" rgba="0.7 0.7 0 1"/>
		<tendon/>
		<motor ctrlrange="-3 3"/>
	</default>
	<option gravity="0 0 -9.81" integrator="RK4" timestep="0.02"/>
	<size nstack="3000"/>

	<visual>
        <map force="0.1" zfar="30"/>
        <rgba haze="0.15 0.25 0.35 1"/>
        <quality shadowsize="2048"/>
        <global offwidth="800" offheight="800"/>
    </visual>

	<asset>
        <texture type="skybox" builtin="gradient" rgb1="0.3 0.5 0.7" rgb2="0 0 0" width="512" height="512"/>
        <texture name="texplane" type="2d" builtin="checker" rgb1=".2 .3 .4" rgb2=".1 0.15 0.2" width="512" height="512" mark="cross" markrgb=".8 .8 .8"/>
        <texture name="texgeom" type="cube" builtin="flat" mark="cross" width="127" height="1278" rgb1="0.8 0.6 0.4" rgb2="0.8 0.6 0.4" markrgb="1 1 1" random="0.01"/>
        <material name="matplane" reflectance="0.3" texture="texplane" texrepeat="1 1" texuniform="true"/>
        <material name="matgeom" texture="texgeom" texuniform="true" rgba="0.8 0.6 .4 1"/>
    </asset>

	<worldbody>
		<geom name="floor" pos="0 0 -0.285" size="0 0 .25" type="plane" material="matplane" condim="3" contype="1" conaffinity="1"/>
        <light directional="false" diffuse=".2 .2 .2" specular="0 0 0" pos="0 0 5" dir="0 0 -1" castshadow="false"/>
        <light mode="targetbodycom" target="cart" directional="false" diffuse=".8 .8 .8" specular="0.3 0.3 0.3" pos="0 0 4.0" dir="0 0 -1"/>
		<!--geom name="ground" type="plane" pos="0 0 0" /-->
		<geom name="rail" pos="0 0 0" quat="0.707 0 0.707 0" rgba="0.3 0.3 0.7 1" size="0.02 1" type="capsule"/>
		<body name="cart" pos="0 0 0">
			<joint axis="1 0 0" limited="true" name="slider" pos="0 0 0" range="-1 1" type="slide"/>
			<geom name="cart" pos="0 0 0" quat="0.707 0 0.707 0" size="0.1 0.1" type="capsule"/>
			<body name="pole" pos="0 0 0">
				<joint axis="0 1 0" name="hinge" pos="0 0 0" range="-90 90" type="hinge"/>
				<geom fromto="0 0 0 0 0 0.6" name="cpole" rgba="0 0.7 0.7 1" size="0.049 0.3" type="capsule"/>
				<!--                 <body name="pole2" pos="0.001 0 0.6"><joint name="hinge2" type="hinge" pos="0 0 0" axis="0 1 0"/><geom name="cpole2" type="capsule" fromto="0 0 0 0 0 0.6" size="0.05 0.3" rgba="0.7 0 0.7 1"/><site name="tip2" pos="0 0 .6"/></body>-->
			</body>
		</body>
	</worldbody>
	<actuator>
		<motor ctrllimited="true" ctrlrange="-3 3" gear="100" joint="slider" name="slide"/>
	</actuator>

	<sensor>
		<jointpos joint="slider" name="slider"/>
		<jointpos joint="hinge" name="hinge"/>
	</sensor>
</mujoco>